<?xml version='1.0'?>
<robot xmlns:xacro="http://www.ros.org/wiki/xacro">
<xacro:include filename="$(find quadwheel)/model/rim.xacro"/>
<xacro:macro name="connector" params="name parent xyz rpy GAZEBO_color">
  <link name="C${name}">
    <inertial>
      <origin xyz="0 0 -0.0286" rpy="0 0 0" />
      <mass value="0.10"/>
      <inertia ixx="7.6e-5" ixy="0.0" ixz="0.0" iyy="7.6e-5" iyz="0.0" izz="0.000125"/>
    </inertial>

    <visual>
      <origin xyz="0 0 -0.0286" rpy="0 0 0" />
      <geometry>
        <cylinder radius="0.0318" length="0.0572"/>
      </geometry>
    </visual>

  </link>

  <joint name="${parent}_C${name}_joint" type="continuous">
    <parent link="${parent}"/>
    <child link="C${name}"/>
    <origin xyz = "${xyz}" rpy = "${rpy}"/>
    <axis xyz = "0 0 1"/>
  </joint>

  <!--Wheel Rims -->
  <xacro:rim name="wheel_${name}" parent="C${name}" xyz="0 0 -0.0572" rpy="0 0 0" GAZEBO_color = "${GAZEBO_color}"/>
 
<gazebo reference="C${name}">
  <mu>0.2</mu>
  <mu2>0.2</mu2>
  <material value= "${GAZEBO_color}"/>
</gazebo>

</xacro:macro>
</robot>
