<?xml version="1.0"?>
<robot name="Robot1">

<!-- Materials -->
<material name="grey">
<color rgba="0.5 0.5 0.5 1"/>
</material>
<material name="yellow_tr">
<color rgba="1 0.75 0 0.5"/>
</material>

<!-- links-->
<!-- World -->
<link name="world"/>

<joint name="fixed" type="fixed">
<parent link="world"/>
<child link="base_link"/>
<origin rpy="0 0 0" xyz="0 0 0.1"/>
</joint>



<!-- Chassis -->
<link name="base_link">
<visual>
<geometry>
<cylinder length="0.126" radius="0.305"/>
</geometry>
<material name="yellow_tr"/>
</visual>

<!-- Gazebo -->
<collision>
<origin xyz="0 0 0" rpy="0 0 0" />
<geometry>
<cylinder length="0.126" radius="0.305"/>
</geometry>
</collision>
<inertial>
<origin xyz="0 0 0" rpy="0 0 0" />
<mass value="1"/>
<inertia
ixx="0.0001" ixy="0.0" ixz="0.0"
iyy="0.0001" iyz="0.0"
izz="0.0001"/>
</inertial>
</link>


<!-- Wheel 1 -->

<link name="wheel_1">
<visual>
<geometry>
<cylinder length="0.038" radius="0.1"/>
<origin rpy="0 0 0" xyz="0 0 0"/>
</geometry>
<material name="grey"/>
</visual>

<!-- Gazebo -->
<collision>
<origin xyz="0 0 0" rpy="0 0 0" />
<geometry>
<cylinder length="0.038" radius="0.1"/>
</geometry>
</collision>
<inertial>
<origin xyz="0 0 0" rpy="0 0 0" />
<mass value="1"/>
<inertia
ixx="0.0001" ixy="0.0" ixz="0.0"
iyy="0.0001" iyz="0.0"
izz="0.0001"/>
</inertial>
</link>


<!-- Wheel 2 -->

<link name="wheel_2">
<visual>
<geometry>
<cylinder length="0.038" radius="0.1"/>
<origin rpy="0 0 0" xyz="0 0 0"/>
</geometry>
<material name="grey"/>
</visual>

<!-- Gazebo -->
<collision>
<origin xyz="0 0 0" rpy="0 0 0" />
<geometry>
<cylinder length="0.038" radius="0.1"/>
</geometry>
</collision>
<inertial>
<origin xyz="0 0 0" rpy="0 0 0" />
<mass value="1"/>
<inertia
ixx="0.0001" ixy="0.0" ixz="0.0"
iyy="0.0001" iyz="0.0"
izz="0.0001"/>
</inertial>
</link>


<!-- Wheel 3 -->

<link name="wheel_3">
<visual>
<geometry>
<cylinder length="0.038" radius="0.1"/>
<origin rpy="0 0 0" xyz="0 0 0"/>
</geometry>
<material name="grey"/>
</visual>

<!-- Gazebo -->
<collision>
<origin xyz="0 0 0" rpy="0 0 0" />
<geometry>
<cylinder length="0.038" radius="0.1"/>
</geometry>
</collision>
<inertial>
<origin xyz="0 0 0" rpy="0 0 0" />
<mass value="1"/>
<inertia
ixx="0.0001" ixy="0.0" ixz="0.0"
iyy="0.0001" iyz="0.0"
izz="0.0001"/>
</inertial>
</link>


<!-- Joints -->
<joint name="base_to_w1" type="continuous">
<parent link="base_link"/>
<child link="wheel_1"/>
<origin rpy="1.57 0 1.57" xyz="0.286 0 0"/>
<axis xyz="0 0 1" />
<dynamics damping="0.7"/>
</joint>

<joint name="base_to_w2" type="continuous">
<parent link="base_link"/>
<child link="wheel_2"/>
<origin rpy="1.57 0 -2.618" xyz="-0.143 0.2477 0"/>
<axis xyz="0 0 1" />
<dynamics damping="0.7"/>
</joint>

<joint name="base_to_w3" type="continuous">
<parent link="base_link"/>
<child link="wheel_3"/>
<origin rpy="1.57 0 -0.5236" xyz="-0.143 -0.2477 0"/>
<axis xyz="0 0 1" />
<dynamics damping="0.7"/>
</joint>

<!-- Gazebo Transmission -->
<!-- Motor 1-->
<transmission name="tran1">
<type>transmission_interface/SimpleTransmission</type>
<joint name="base_to_w1">
<hardwareInterface>hardware_interface/EffortJointInterface</hardwareInterface>
</joint>
<actuator name="motor1">
<hardwareInterface>hardware_interface/EffortJointInterface</hardwareInterface>
<mechanicalReduction>1</mechanicalReduction>
</actuator>
</transmission>

<!-- Motor 2-->
<transmission name="tran2">
<type>transmission_interface/SimpleTransmission</type>
<joint name="base_to_w2">
<hardwareInterface>hardware_interface/EffortJointInterface</hardwareInterface>
</joint>
<actuator name="motor2">
<hardwareInterface>hardware_interface/EffortJointInterface</hardwareInterface>
<mechanicalReduction>1</mechanicalReduction>
</actuator>
</transmission>

<!-- Motor 3-->
<transmission name="tran3">
<type>transmission_interface/SimpleTransmission</type>
<joint name="base_to_w3">
<hardwareInterface>hardware_interface/EffortJointInterface</hardwareInterface>
</joint>
<actuator name="motor3">
<hardwareInterface>hardware_interface/EffortJointInterface</hardwareInterface>
<mechanicalReduction>1</mechanicalReduction>
</actuator>
</transmission>


</robot>
